2025-06-29 12:26:42,240 — INFO — Starting Automation Project...
2025-06-29 12:26:42,241 — INFO — Running SMTP sender...
2025-06-29 12:26:42,428 — INFO — [DRY RUN] Would send to test1@example.net using user1@example.com
2025-06-29 12:26:42,431 — INFO — [DRY RUN] Would send to test2@example.net using user2@example.com
2025-06-29 12:34:41,682 — INFO — Starting Automation Project...
2025-06-29 12:34:41,683 — INFO — Running SMTP sender...
2025-06-29 12:34:41,941 — INFO — [DRY RUN] Would send to serova.ekat1@gmail.com using user1@example.com
2025-06-29 12:34:41,944 — INFO — [DRY RUN] Would send to test2@example.com using user2@example.com
2025-06-30 13:49:16,455 — INFO — Starting Automation Project...
2025-06-30 13:49:16,457 — INFO — Running SMTP sender...
2025-06-30 13:49:16,979 — INFO — [DRY RUN] Would send to serova.ekat1@gmail.com using user1@example.com
2025-06-30 13:49:19,635 — INFO — [DRY RUN] Would send to test2@example.com using user1@example.com
2025-06-30 13:57:32,420 — INFO — Starting Automation Project...
2025-06-30 13:57:32,422 — INFO — Running SMTP sender...
2025-06-30 13:57:32,747 — INFO — [DRY RUN] Would send to serova.ekat1@gmail.com using user1@example.com
2025-06-30 13:57:36,763 — INFO — [DRY RUN] Would send to test2@example.com using user1@example.com
2025-07-01 00:16:11,039 — INFO — Starting Automation Project...
2025-07-01 00:16:11,041 — INFO — Running SMTP sender...
2025-07-01 00:16:11,404 — INFO — [DRY RUN] Would send to serova.ekat1@gmail.com using mell3@gmx.ch
2025-07-01 00:16:13,779 — INFO — [DRY RUN] Would send to test2@example.com using mell3@gmx.ch
2025-07-01 00:18:45,222 — INFO — Starting Automation Project...
2025-07-01 00:18:45,224 — INFO — Running SMTP sender...
2025-07-01 00:18:54,304 — INFO — Sent to serova.ekat1@gmail.com using mell3@gmx.ch
2025-07-01 00:19:03,184 — ERROR — Failed to send to test2@example.com using mell3@gmx.ch: [SMTPRecipientRefused(556, 'Requested action not taken: domain does not accept mail\ninvalid DNS MX or A/AAAA resource record 1MoO24-1v39Z80nzk-00gvMy', 'test2@example.com')]
2025-07-01 00:19:03,186 — WARNING — SMTP account mell3@gmx.ch marked as invalid and removed.
2025-07-01 00:19:07,211 — ERROR — Fatal error on SSL transport
protocol: <asyncio.sslproto.SSLProtocol object at 0x70330ffc1720>
transport: <_SelectorSocketTransport closing fd=7>
Traceback (most recent call last):
  File "/usr/lib/python3.10/asyncio/selector_events.py", line 924, in write
    n = self._sock.send(data)
OSError: [Errno 9] Bad file descriptor

During handling of the above exception, another exception occurred:

Traceback (most recent call last):
  File "/usr/lib/python3.10/asyncio/sslproto.py", line 690, in _process_write_backlog
    self._transport.write(chunk)
  File "/usr/lib/python3.10/asyncio/selector_events.py", line 930, in write
    self._fatal_error(exc, 'Fatal write error on socket transport')
  File "/usr/lib/python3.10/asyncio/selector_events.py", line 725, in _fatal_error
    self._force_close(exc)
  File "/usr/lib/python3.10/asyncio/selector_events.py", line 737, in _force_close
    self._loop.call_soon(self._call_connection_lost, exc)
  File "/usr/lib/python3.10/asyncio/base_events.py", line 753, in call_soon
    self._check_closed()
  File "/usr/lib/python3.10/asyncio/base_events.py", line 515, in _check_closed
    raise RuntimeError('Event loop is closed')
RuntimeError: Event loop is closed
2025-07-01 00:32:54,765 — INFO — Starting Automation Project...
2025-07-01 00:32:54,766 — INFO — Running SMTP sender...
2025-07-01 00:33:01,240 — INFO — Sent to serova.ekat1@gmail.com using mell3@gmx.ch
2025-07-01 00:33:12,022 — ERROR — Failed to send to test2@example.com using mell3@gmx.ch: [SMTPRecipientRefused(556, 'Requested action not taken: domain does not accept mail\ninvalid DNS MX or A/AAAA resource record 1MhlKy-1vA6id1u2y-00pPx6', 'test2@example.com')]
2025-07-01 00:33:14,248 — ERROR — Fatal error on SSL transport
protocol: <asyncio.sslproto.SSLProtocol object at 0x7ca630c117b0>
transport: <_SelectorSocketTransport closing fd=7>
Traceback (most recent call last):
  File "/usr/lib/python3.10/asyncio/selector_events.py", line 924, in write
    n = self._sock.send(data)
OSError: [Errno 9] Bad file descriptor

During handling of the above exception, another exception occurred:

Traceback (most recent call last):
  File "/usr/lib/python3.10/asyncio/sslproto.py", line 690, in _process_write_backlog
    self._transport.write(chunk)
  File "/usr/lib/python3.10/asyncio/selector_events.py", line 930, in write
    self._fatal_error(exc, 'Fatal write error on socket transport')
  File "/usr/lib/python3.10/asyncio/selector_events.py", line 725, in _fatal_error
    self._force_close(exc)
  File "/usr/lib/python3.10/asyncio/selector_events.py", line 737, in _force_close
    self._loop.call_soon(self._call_connection_lost, exc)
  File "/usr/lib/python3.10/asyncio/base_events.py", line 753, in call_soon
    self._check_closed()
  File "/usr/lib/python3.10/asyncio/base_events.py", line 515, in _check_closed
    raise RuntimeError('Event loop is closed')
RuntimeError: Event loop is closed
