2025-06-29 12:26:42,240 — INFO — Starting Automation Project...
2025-06-29 12:26:42,241 — INFO — Running SMTP sender...
2025-06-29 12:26:42,428 — INFO — [DRY RUN] Would send to test1@example.net using user1@example.com
2025-06-29 12:26:42,431 — INFO — [DRY RUN] Would send to test2@example.net using user2@example.com
2025-06-29 12:34:41,682 — INFO — Starting Automation Project...
2025-06-29 12:34:41,683 — INFO — Running SMTP sender...
2025-06-29 12:34:41,941 — INFO — [DRY RUN] Would send to serova.ekat1@gmail.com using user1@example.com
2025-06-29 12:34:41,944 — INFO — [DRY RUN] Would send to test2@example.com using user2@example.com
2025-06-30 13:49:16,455 — INFO — Starting Automation Project...
2025-06-30 13:49:16,457 — INFO — Running SMTP sender...
2025-06-30 13:49:16,979 — INFO — [DRY RUN] Would send to serova.ekat1@gmail.com using user1@example.com
2025-06-30 13:49:19,635 — INFO — [DRY RUN] Would send to test2@example.com using user1@example.com
2025-06-30 13:57:32,420 — INFO — Starting Automation Project...
2025-06-30 13:57:32,422 — INFO — Running SMTP sender...
2025-06-30 13:57:32,747 — INFO — [DRY RUN] Would send to serova.ekat1@gmail.com using user1@example.com
2025-06-30 13:57:36,763 — INFO — [DRY RUN] Would send to test2@example.com using user1@example.com
2025-07-01 00:16:11,039 — INFO — Starting Automation Project...
2025-07-01 00:16:11,041 — INFO — Running SMTP sender...
2025-07-01 00:16:11,404 — INFO — [DRY RUN] Would send to serova.ekat1@gmail.com using mell3@gmx.ch
2025-07-01 00:16:13,779 — INFO — [DRY RUN] Would send to test2@example.com using mell3@gmx.ch
2025-07-01 00:18:45,222 — INFO — Starting Automation Project...
2025-07-01 00:18:45,224 — INFO — Running SMTP sender...
2025-07-01 00:18:54,304 — INFO — Sent to serova.ekat1@gmail.com using mell3@gmx.ch
2025-07-01 00:19:03,184 — ERROR — Failed to send to test2@example.com using mell3@gmx.ch: [SMTPRecipientRefused(556, 'Requested action not taken: domain does not accept mail\ninvalid DNS MX or A/AAAA resource record 1MoO24-1v39Z80nzk-00gvMy', 'test2@example.com')]
2025-07-01 00:19:03,186 — WARNING — SMTP account mell3@gmx.ch marked as invalid and removed.
2025-07-01 00:19:07,211 — ERROR — Fatal error on SSL transport
protocol: <asyncio.sslproto.SSLProtocol object at 0x70330ffc1720>
transport: <_SelectorSocketTransport closing fd=7>
Traceback (most recent call last):
  File "/usr/lib/python3.10/asyncio/selector_events.py", line 924, in write
    n = self._sock.send(data)
OSError: [Errno 9] Bad file descriptor

During handling of the above exception, another exception occurred:

Traceback (most recent call last):
  File "/usr/lib/python3.10/asyncio/sslproto.py", line 690, in _process_write_backlog
    self._transport.write(chunk)
  File "/usr/lib/python3.10/asyncio/selector_events.py", line 930, in write
    self._fatal_error(exc, 'Fatal write error on socket transport')
  File "/usr/lib/python3.10/asyncio/selector_events.py", line 725, in _fatal_error
    self._force_close(exc)
  File "/usr/lib/python3.10/asyncio/selector_events.py", line 737, in _force_close
    self._loop.call_soon(self._call_connection_lost, exc)
  File "/usr/lib/python3.10/asyncio/base_events.py", line 753, in call_soon
    self._check_closed()
  File "/usr/lib/python3.10/asyncio/base_events.py", line 515, in _check_closed
    raise RuntimeError('Event loop is closed')
RuntimeError: Event loop is closed
2025-07-01 00:32:54,765 — INFO — Starting Automation Project...
2025-07-01 00:32:54,766 — INFO — Running SMTP sender...
2025-07-01 00:33:01,240 — INFO — Sent to serova.ekat1@gmail.com using mell3@gmx.ch
2025-07-01 00:33:12,022 — ERROR — Failed to send to test2@example.com using mell3@gmx.ch: [SMTPRecipientRefused(556, 'Requested action not taken: domain does not accept mail\ninvalid DNS MX or A/AAAA resource record 1MhlKy-1vA6id1u2y-00pPx6', 'test2@example.com')]
2025-07-01 00:33:14,248 — ERROR — Fatal error on SSL transport
protocol: <asyncio.sslproto.SSLProtocol object at 0x7ca630c117b0>
transport: <_SelectorSocketTransport closing fd=7>
Traceback (most recent call last):
  File "/usr/lib/python3.10/asyncio/selector_events.py", line 924, in write
    n = self._sock.send(data)
OSError: [Errno 9] Bad file descriptor

During handling of the above exception, another exception occurred:

Traceback (most recent call last):
  File "/usr/lib/python3.10/asyncio/sslproto.py", line 690, in _process_write_backlog
    self._transport.write(chunk)
  File "/usr/lib/python3.10/asyncio/selector_events.py", line 930, in write
    self._fatal_error(exc, 'Fatal write error on socket transport')
  File "/usr/lib/python3.10/asyncio/selector_events.py", line 725, in _fatal_error
    self._force_close(exc)
  File "/usr/lib/python3.10/asyncio/selector_events.py", line 737, in _force_close
    self._loop.call_soon(self._call_connection_lost, exc)
  File "/usr/lib/python3.10/asyncio/base_events.py", line 753, in call_soon
    self._check_closed()
  File "/usr/lib/python3.10/asyncio/base_events.py", line 515, in _check_closed
    raise RuntimeError('Event loop is closed')
RuntimeError: Event loop is closed
2025-07-02 01:04:47,463 — INFO — Starting Automation Project...
2025-07-02 01:04:47,466 — INFO — Running email checker...
2025-07-02 01:05:16,129 — INFO — Email check completed.
2025-07-02 01:05:16,173 — ERROR — Fatal error on SSL transport
protocol: <asyncio.sslproto.SSLProtocol object at 0x7f072048b220>
transport: <_SelectorSocketTransport closing fd=26>
Traceback (most recent call last):
  File "/usr/lib/python3.10/asyncio/selector_events.py", line 924, in write
    n = self._sock.send(data)
OSError: [Errno 9] Bad file descriptor

During handling of the above exception, another exception occurred:

Traceback (most recent call last):
  File "/usr/lib/python3.10/asyncio/sslproto.py", line 690, in _process_write_backlog
    self._transport.write(chunk)
  File "/usr/lib/python3.10/asyncio/selector_events.py", line 930, in write
    self._fatal_error(exc, 'Fatal write error on socket transport')
  File "/usr/lib/python3.10/asyncio/selector_events.py", line 725, in _fatal_error
    self._force_close(exc)
  File "/usr/lib/python3.10/asyncio/selector_events.py", line 737, in _force_close
    self._loop.call_soon(self._call_connection_lost, exc)
  File "/usr/lib/python3.10/asyncio/base_events.py", line 753, in call_soon
    self._check_closed()
  File "/usr/lib/python3.10/asyncio/base_events.py", line 515, in _check_closed
    raise RuntimeError('Event loop is closed')
RuntimeError: Event loop is closed
2025-07-02 01:05:16,188 — ERROR — Fatal error on SSL transport
protocol: <asyncio.sslproto.SSLProtocol object at 0x7f07215ebf40>
transport: <_SelectorSocketTransport closing fd=10>
Traceback (most recent call last):
  File "/usr/lib/python3.10/asyncio/selector_events.py", line 924, in write
    n = self._sock.send(data)
OSError: [Errno 9] Bad file descriptor

During handling of the above exception, another exception occurred:

Traceback (most recent call last):
  File "/usr/lib/python3.10/asyncio/sslproto.py", line 690, in _process_write_backlog
    self._transport.write(chunk)
  File "/usr/lib/python3.10/asyncio/selector_events.py", line 930, in write
    self._fatal_error(exc, 'Fatal write error on socket transport')
  File "/usr/lib/python3.10/asyncio/selector_events.py", line 725, in _fatal_error
    self._force_close(exc)
  File "/usr/lib/python3.10/asyncio/selector_events.py", line 737, in _force_close
    self._loop.call_soon(self._call_connection_lost, exc)
  File "/usr/lib/python3.10/asyncio/base_events.py", line 753, in call_soon
    self._check_closed()
  File "/usr/lib/python3.10/asyncio/base_events.py", line 515, in _check_closed
    raise RuntimeError('Event loop is closed')
RuntimeError: Event loop is closed
2025-07-02 01:05:16,190 — ERROR — Fatal error on SSL transport
protocol: <asyncio.sslproto.SSLProtocol object at 0x7f0720489150>
transport: <_SelectorSocketTransport closing fd=21>
Traceback (most recent call last):
  File "/usr/lib/python3.10/asyncio/selector_events.py", line 924, in write
    n = self._sock.send(data)
OSError: [Errno 9] Bad file descriptor

During handling of the above exception, another exception occurred:

Traceback (most recent call last):
  File "/usr/lib/python3.10/asyncio/sslproto.py", line 690, in _process_write_backlog
    self._transport.write(chunk)
  File "/usr/lib/python3.10/asyncio/selector_events.py", line 930, in write
    self._fatal_error(exc, 'Fatal write error on socket transport')
  File "/usr/lib/python3.10/asyncio/selector_events.py", line 725, in _fatal_error
    self._force_close(exc)
  File "/usr/lib/python3.10/asyncio/selector_events.py", line 737, in _force_close
    self._loop.call_soon(self._call_connection_lost, exc)
  File "/usr/lib/python3.10/asyncio/base_events.py", line 753, in call_soon
    self._check_closed()
  File "/usr/lib/python3.10/asyncio/base_events.py", line 515, in _check_closed
    raise RuntimeError('Event loop is closed')
RuntimeError: Event loop is closed
2025-07-02 01:05:16,192 — ERROR — Fatal error on SSL transport
protocol: <asyncio.sslproto.SSLProtocol object at 0x7f072048add0>
transport: <_SelectorSocketTransport closing fd=12>
Traceback (most recent call last):
  File "/usr/lib/python3.10/asyncio/selector_events.py", line 924, in write
    n = self._sock.send(data)
OSError: [Errno 9] Bad file descriptor

During handling of the above exception, another exception occurred:

Traceback (most recent call last):
  File "/usr/lib/python3.10/asyncio/sslproto.py", line 690, in _process_write_backlog
    self._transport.write(chunk)
  File "/usr/lib/python3.10/asyncio/selector_events.py", line 930, in write
    self._fatal_error(exc, 'Fatal write error on socket transport')
  File "/usr/lib/python3.10/asyncio/selector_events.py", line 725, in _fatal_error
    self._force_close(exc)
  File "/usr/lib/python3.10/asyncio/selector_events.py", line 737, in _force_close
    self._loop.call_soon(self._call_connection_lost, exc)
  File "/usr/lib/python3.10/asyncio/base_events.py", line 753, in call_soon
    self._check_closed()
  File "/usr/lib/python3.10/asyncio/base_events.py", line 515, in _check_closed
    raise RuntimeError('Event loop is closed')
RuntimeError: Event loop is closed
2025-07-02 01:05:16,194 — ERROR — Fatal error on SSL transport
protocol: <asyncio.sslproto.SSLProtocol object at 0x7f07215eb1c0>
transport: <_SelectorSocketTransport closing fd=16>
Traceback (most recent call last):
  File "/usr/lib/python3.10/asyncio/selector_events.py", line 924, in write
    n = self._sock.send(data)
OSError: [Errno 9] Bad file descriptor

During handling of the above exception, another exception occurred:

Traceback (most recent call last):
  File "/usr/lib/python3.10/asyncio/sslproto.py", line 690, in _process_write_backlog
    self._transport.write(chunk)
  File "/usr/lib/python3.10/asyncio/selector_events.py", line 930, in write
    self._fatal_error(exc, 'Fatal write error on socket transport')
  File "/usr/lib/python3.10/asyncio/selector_events.py", line 725, in _fatal_error
    self._force_close(exc)
  File "/usr/lib/python3.10/asyncio/selector_events.py", line 737, in _force_close
    self._loop.call_soon(self._call_connection_lost, exc)
  File "/usr/lib/python3.10/asyncio/base_events.py", line 753, in call_soon
    self._check_closed()
  File "/usr/lib/python3.10/asyncio/base_events.py", line 515, in _check_closed
    raise RuntimeError('Event loop is closed')
RuntimeError: Event loop is closed
2025-07-02 01:05:16,196 — ERROR — Fatal error on SSL transport
protocol: <asyncio.sslproto.SSLProtocol object at 0x7f07215eb6a0>
transport: <_SelectorSocketTransport closing fd=11>
Traceback (most recent call last):
  File "/usr/lib/python3.10/asyncio/selector_events.py", line 924, in write
    n = self._sock.send(data)
OSError: [Errno 9] Bad file descriptor

During handling of the above exception, another exception occurred:

Traceback (most recent call last):
  File "/usr/lib/python3.10/asyncio/sslproto.py", line 690, in _process_write_backlog
    self._transport.write(chunk)
  File "/usr/lib/python3.10/asyncio/selector_events.py", line 930, in write
    self._fatal_error(exc, 'Fatal write error on socket transport')
  File "/usr/lib/python3.10/asyncio/selector_events.py", line 725, in _fatal_error
    self._force_close(exc)
  File "/usr/lib/python3.10/asyncio/selector_events.py", line 737, in _force_close
    self._loop.call_soon(self._call_connection_lost, exc)
  File "/usr/lib/python3.10/asyncio/base_events.py", line 753, in call_soon
    self._check_closed()
  File "/usr/lib/python3.10/asyncio/base_events.py", line 515, in _check_closed
    raise RuntimeError('Event loop is closed')
RuntimeError: Event loop is closed
2025-07-02 01:05:16,198 — ERROR — Fatal error on SSL transport
protocol: <asyncio.sslproto.SSLProtocol object at 0x7f07215e9960>
transport: <_SelectorSocketTransport closing fd=8>
Traceback (most recent call last):
  File "/usr/lib/python3.10/asyncio/selector_events.py", line 924, in write
    n = self._sock.send(data)
OSError: [Errno 9] Bad file descriptor

During handling of the above exception, another exception occurred:

Traceback (most recent call last):
  File "/usr/lib/python3.10/asyncio/sslproto.py", line 690, in _process_write_backlog
    self._transport.write(chunk)
  File "/usr/lib/python3.10/asyncio/selector_events.py", line 930, in write
    self._fatal_error(exc, 'Fatal write error on socket transport')
  File "/usr/lib/python3.10/asyncio/selector_events.py", line 725, in _fatal_error
    self._force_close(exc)
  File "/usr/lib/python3.10/asyncio/selector_events.py", line 737, in _force_close
    self._loop.call_soon(self._call_connection_lost, exc)
  File "/usr/lib/python3.10/asyncio/base_events.py", line 753, in call_soon
    self._check_closed()
  File "/usr/lib/python3.10/asyncio/base_events.py", line 515, in _check_closed
    raise RuntimeError('Event loop is closed')
RuntimeError: Event loop is closed
2025-07-02 01:15:27,491 — INFO — Starting Automation Project...
2025-07-02 01:15:27,491 — INFO — Running email checker...
2025-07-02 01:16:01,400 — INFO — Email check completed.
2025-07-02 23:29:01,997 — INFO — Starting Automation Project...
2025-07-02 23:29:12,968 — INFO — Starting Automation Project...
2025-07-02 23:29:48,862 — INFO — Starting Automation Project...
2025-07-02 23:29:57,381 — INFO — Starting Automation Project...
2025-07-02 23:30:05,077 — INFO — Starting Automation Project...
2025-07-02 23:37:22,748 — INFO — Starting Automation Project...
2025-07-02 23:37:22,752 — ERROR — Failed to add accounts from CSV: [Errno 2] No such file or directory: '/mnt/data/smtp_accounts_sample.csv'
2025-07-02 23:38:07,470 — INFO — Starting Automation Project...
2025-07-02 23:38:07,474 — ERROR — Failed to add accounts from CSV: [Errno 2] No such file or directory: '/mnt/data/smtp_accounts_sample.csv'
2025-07-02 23:38:48,201 — INFO — Starting Automation Project...
2025-07-02 23:38:48,204 — ERROR — Failed to add accounts from CSV: [Errno 2] No such file or directory: '/data/smtp_accounts_sample.csv'
2025-07-02 23:39:50,562 — INFO — Starting Automation Project...
2025-07-02 23:40:17,584 — INFO — Starting Automation Project...
2025-07-02 23:48:03,557 — INFO — Starting Automation Project...
2025-07-02 23:48:03,557 — INFO — Running SMTP sender...
2025-07-02 23:48:03,772 — INFO — [DRY RUN] Would send to vasya11@mail.ru using mentaldagod@gmx.ch
2025-07-02 23:48:08,628 — INFO — [DRY RUN] Would send to ivan.petrov@gmail.com using mhmdanas48@gmx.ch
2025-07-02 23:48:13,450 — INFO — [DRY RUN] Would send to test15@mail.ru using mhmdanas48@gmx.ch
2025-07-02 23:48:15,464 — INFO — [DRY RUN] Would send to test18@bk.ru using mell3@gmx.ch
2025-07-02 23:48:19,232 — INFO — [DRY RUN] Would send to test19@list.ru using mentaldagod@gmx.ch
2025-07-02 23:48:22,420 — INFO — [DRY RUN] Would send to test20@inbox.ru using mhmdanas48@gmx.ch
2025-07-02 23:48:25,094 — INFO — [DRY RUN] Would send to nosuchperson12345678@mail.ru using mell3@gmx.ch
2025-07-03 00:00:12,948 — INFO — Starting Automation Project...
2025-07-03 00:00:12,949 — INFO — Running SMTP sender...
2025-07-03 00:00:13,106 — INFO — [DRY RUN] Would send to vasya11@mail.ru using mell3@gmx.ch
2025-07-03 00:00:15,188 — INFO — [DRY RUN] Would send to ivan.petrov@gmail.com using mhmdanas48@gmx.ch
2025-07-03 00:00:19,592 — INFO — [DRY RUN] Would send to test15@mail.ru using mell3@gmx.ch
2025-07-03 00:00:23,029 — INFO — [DRY RUN] Would send to test18@bk.ru using mhmdanas48@gmx.ch
2025-07-03 00:00:27,041 — INFO — [DRY RUN] Would send to test19@list.ru using mentaldagod@gmx.ch
2025-07-03 00:00:31,615 — INFO — [DRY RUN] Would send to test20@inbox.ru using mell3@gmx.ch
2025-07-03 00:00:34,770 — INFO — [DRY RUN] Would send to nosuchperson12345678@mail.ru using mell3@gmx.ch
2025-07-03 00:06:26,961 — INFO — Starting Automation Project...
2025-07-03 00:06:26,962 — INFO — Running integrated workflow...
2025-07-03 00:06:26,963 — INFO — [WORKFLOW] Запуск полного пайплайна...
2025-07-03 00:06:26,963 — INFO — [WORKFLOW] Шаг 1: Парсинг объявлений с tutti.ch...
2025-07-03 00:07:09,211 — INFO — [WORKFLOW] Парсинг завершён. Сохранено: 0 записей.
2025-07-03 00:07:09,288 — INFO — [WORKFLOW] Шаг 2: Генерация и валидация email-адресов...
2025-07-03 00:07:45,091 — INFO — [WORKFLOW] Email-чекер завершён.
2025-07-03 00:07:45,092 — INFO — [WORKFLOW] Шаг 3: Рассылка писем...
2025-07-03 00:07:45,117 — INFO — [DRY RUN] Would send to vasya11@mail.ru using mhmdanas48@gmx.ch
2025-07-03 00:07:49,792 — INFO — [DRY RUN] Would send to ivan.petrov@gmail.com using mentaldagod@gmx.ch
2025-07-03 00:07:54,106 — INFO — [DRY RUN] Would send to test15@mail.ru using mell3@gmx.ch
2025-07-03 00:07:56,940 — INFO — [DRY RUN] Would send to test18@bk.ru using mentaldagod@gmx.ch
2025-07-03 00:07:59,180 — INFO — [DRY RUN] Would send to test19@list.ru using mhmdanas48@gmx.ch
2025-07-03 00:08:03,246 — INFO — [DRY RUN] Would send to test20@inbox.ru using mentaldagod@gmx.ch
2025-07-03 00:08:06,467 — INFO — [DRY RUN] Would send to nosuchperson12345678@mail.ru using mhmdanas48@gmx.ch
2025-07-03 00:08:08,877 — INFO — [WORKFLOW] Рассылка завершена.
2025-07-03 00:16:12,467 — INFO — Starting Automation Project...
2025-07-03 00:16:12,467 — INFO — Running integrated workflow...
2025-07-03 00:16:12,468 — INFO — [WORKFLOW] Запуск полного пайплайна...
2025-07-03 00:16:12,469 — INFO — [WORKFLOW] Парсинг объявлений
2025-07-03 00:16:54,593 — INFO — [WORKFLOW] Парсинг завершён. Сохранено: 0 записей.
2025-07-03 00:16:54,680 — INFO — [WORKFLOW] Генерация и валидация email-адресов...
2025-07-03 00:17:23,956 — INFO — [WORKFLOW] Проверка e-mail адресов завершена.
2025-07-03 00:17:23,958 — INFO — [WORKFLOW] Отправка писем...
2025-07-03 00:17:23,989 — INFO — [ТЕСТ] Письмо бы отправилось на vasya11@mail.ru через mhmdanas48@gmx.ch
2025-07-03 00:17:26,603 — INFO — [ТЕСТ] Письмо бы отправилось на ivan.petrov@gmail.com через mentaldagod@gmx.ch
2025-07-03 00:17:30,952 — INFO — [ТЕСТ] Письмо бы отправилось на test15@mail.ru через mentaldagod@gmx.ch
2025-07-03 00:17:35,219 — INFO — [ТЕСТ] Письмо бы отправилось на test18@bk.ru через mhmdanas48@gmx.ch
2025-07-03 00:17:39,562 — INFO — [ТЕСТ] Письмо бы отправилось на test19@list.ru через mhmdanas48@gmx.ch
2025-07-03 00:17:41,949 — INFO — [ТЕСТ] Письмо бы отправилось на test20@inbox.ru через mhmdanas48@gmx.ch
2025-07-03 00:17:44,404 — INFO — [ТЕСТ] Письмо бы отправилось на nosuchperson12345678@mail.ru через mhmdanas48@gmx.ch
2025-07-03 00:17:48,641 — INFO — [WORKFLOW] Рассылка завершена.
